<?xml version="1.0" ?>
<!-- =================================================================================== -->
<!-- |    This document was autogenerated by xacro from /home/user/Desktop/ros2_ws/install/share/kr20_kr120_description/urdf/kr20_kr120.urdf.xacro | -->
<!-- |    EDITING THIS FILE BY HAND IS NOT RECOMMENDED                                 | -->
<!-- =================================================================================== -->
<robot name="kr20_kr120">
  <!-- <xacro:macro name="transmission" params="name joint_name actuator_name">
        <transmission name="${name}" >
            <type>transmission_interface/SimpleTransmission</type>
            <joint name = "${joint_name}" >
                <hardwareInterface>hardware_interface/PositionJointInterface</hardwareInterface>
            </joint>
            <actuator name="${actuator_name}" >
                <hardwareInterface>hardware_interface/PositionJointInterface</hardwareInterface>
                <mechanicalReduction>1</mechanicalReduction>
            </actuator>
        </transmission>
    </xacro:macro> -->
  <!-- <xacro:macro name="transmission" params="name joint_name actuator_name">
        <transmission name="${name}" >
            <type>transmission_interface/SimpleTransmission</type>
            <joint name = "${joint_name}" >
                <hardwareInterface>hardware_interface/PositionJointInterface</hardwareInterface>
            </joint>
            <actuator name="${actuator_name}" >
                <hardwareInterface>hardware_interface/PositionJointInterface</hardwareInterface>
                <mechanicalReduction>1</mechanicalReduction>
            </actuator>
        </transmission>
    </xacro:macro> -->
  <!-- <xacro:macro name="transmission" params="name joint_name actuator_name">
        <transmission name="${name}" >
            <type>transmission_interface/SimpleTransmission</type>
            <joint name = "${joint_name}" >
                <hardwareInterface>hardware_interface/PositionJointInterface</hardwareInterface>
            </joint>
            <actuator name="${actuator_name}" >
                <hardwareInterface>hardware_interface/PositionJointInterface</hardwareInterface>
                <mechanicalReduction>1</mechanicalReduction>
            </actuator>
        </transmission>
    </xacro:macro> -->
  <!-- <xacro:macro name="transmission" params="name joint_name actuator_name">
        <transmission name="${name}" >
            <type>transmission_interface/SimpleTransmission</type>
            <joint name = "${joint_name}" >
                <hardwareInterface>hardware_interface/PositionJointInterface</hardwareInterface>
            </joint>
            <actuator name="${actuator_name}" >
                <hardwareInterface>hardware_interface/PositionJointInterface</hardwareInterface>
                <mechanicalReduction>1</mechanicalReduction>
            </actuator>
        </transmission>
    </xacro:macro> -->
  <!-- <xacro:macro name="transmission" params="name joint_name actuator_name">
        <transmission name="${name}" >
            <type>transmission_interface/SimpleTransmission</type>
            <joint name = "${joint_name}" >
                <hardwareInterface>hardware_interface/PositionJointInterface</hardwareInterface>
            </joint>
            <actuator name="${actuator_name}" >
                <hardwareInterface>hardware_interface/PositionJointInterface</hardwareInterface>
                <mechanicalReduction>1</mechanicalReduction>
            </actuator>
        </transmission>
    </xacro:macro> -->
  <!-- Fix the robot to the world-->
  <link name="world"/>
  <link name="kr20_basamento">
    <inertial>
      <origin rpy="-1.5708 0 0" xyz="0.165 -0.3675 0"/>
      <mass value="1"/>
      <inertia ixx="0.01625" ixy="0" ixz="0" iyy="0.01625" iyz="0" izz="0.005"/>
    </inertial>
    <visual>
      <geometry>
        <mesh filename="/home/user/Desktop/ros2_ws/src/kr20_kr120_description/visual/kr20_basement.dae" scale="0.001 0.001 0.001"/>
      </geometry>
      <origin rpy="-1.5708 0 0" xyz="0.165 -0.3675 0"/>
    </visual>
    <collision>
      <geometry>
        <mesh filename="/home/user/Desktop/ros2_ws/src/kr20_kr120_description/collision/kr20_basement.stl" scale="0.001 0.001 0.001"/>
      </geometry>
      <origin rpy="-1.5708 0 0" xyz="0.165 -0.3675 0"/>
    </collision>
  </link>
  <joint name="kr20_world_fixed" type="fixed">
    <origin rpy="0 0 -1.5708" xyz="0 0 0"/>
    <parent link="world"/>
    <child link="kr20_basamento"/>
  </joint>
  <joint name="kr20_base" type="fixed">
    <origin rpy="0 0 0" xyz="0 0 0"/>
    <parent link="kr20_basamento"/>
    <child link="kr20_base_link"/>
  </joint>
  <link name="kr20_base_link">
    <inertial>
      <origin rpy="0 0 0" xyz="0 0 0.551"/>
      <mass value="1"/>
      <inertia ixx="0.01625" ixy="0" ixz="0" iyy="0.01625" iyz="0" izz="0.005"/>
    </inertial>
    <visual>
      <geometry>
        <mesh filename="/home/user/Desktop/ros2_ws/src/kr20_kr120_description/visual/kr20_base.dae" scale="0.001 0.001 0.001"/>
      </geometry>
      <origin rpy="0 0 0" xyz="0 0 0.551"/>
    </visual>
    <collision>
      <geometry>
        <mesh filename="/home/user/Desktop/ros2_ws/src/kr20_kr120_description/collision/kr20_base.stl" scale="0.001 0.001 0.001"/>
      </geometry>
      <origin rpy="0 0 0" xyz="0 0 0.551"/>
    </collision>
  </link>
  <link name="kr20_link1">
    <inertial>
      <origin rpy="0 0 0" xyz="0 0 0.551"/>
      <mass value="1.5"/>
      <inertia ixx="0.054147" ixy="0" ixz="0" iyy="0.054147" iyz="0" izz="0.001875"/>
    </inertial>
    <visual>
      <geometry>
        <mesh filename="/home/user/Desktop/ros2_ws/src/kr20_kr120_description/visual/kr20_asse1.dae" scale="0.001 0.001 0.001"/>
      </geometry>
      <origin rpy="0 0 0" xyz="0 0 0.551"/>
    </visual>
    <collision>
      <geometry>
        <mesh filename="/home/user/Desktop/ros2_ws/src/kr20_kr120_description/collision/kr20_asse1.stl" scale="0.001 0.001 0.001"/>
      </geometry>
      <origin rpy="0 0 0" xyz="0 0 0.551"/>
    </collision>
  </link>
  <joint name="kr20_base_link__link1" type="revolute">
    <parent link="kr20_base_link"/>
    <child link="kr20_link1"/>
    <axis xyz="0 0 1"/>
    <limit effort="100" lower="-3.22886" upper="3.22886" velocity="3.49066"/>
    <origin rpy="0 0 0" xyz="0 0 0"/>
    <dynamics damping="40" friction="10"/>
  </joint>
  <link name="kr20_link2">
    <inertial>
      <origin rpy="0 0 0" xyz="-0.16 0 -0.52"/>
      <mass value="2"/>
      <inertia ixx="0.4816" ixy="0" ixz="0" iyy="0" iyz="0" izz="0.4816"/>
    </inertial>
    <visual>
      <geometry>
        <mesh filename="/home/user/Desktop/ros2_ws/src/kr20_kr120_description/visual/kr20_asse2.dae" scale="0.001 0.001 0.001"/>
      </geometry>
      <origin rpy="0 0 0" xyz="-0.16 0 -0.52"/>
    </visual>
    <collision>
      <geometry>
        <mesh filename="/home/user/Desktop/ros2_ws/src/kr20_kr120_description/collision/kr20_asse2.stl" scale="0.001 0.001 0.001"/>
      </geometry>
      <origin rpy="0 0 0" xyz="-0.16 0 -0.52"/>
    </collision>
  </link>
  <joint name="kr20_link1__link2" type="revolute">
    <parent link="kr20_link1"/>
    <child link="kr20_link2"/>
    <axis xyz="0 1 0"/>
    <limit effort="100" lower="-1.65806" upper="2.70526" velocity="3.05433"/>
    <origin rpy="0 0 0" xyz="0.16 0 1.071"/>
    <dynamics damping="40" friction="10"/>
  </joint>
  <link name="kr20_link3">
    <inertial>
      <origin rpy="0 0 0" xyz="-0.16 0 -1.3"/>
      <mass value="2"/>
      <inertia ixx="0.4816" ixy="0" ixz="0" iyy="0" iyz="0" izz="0.4816"/>
    </inertial>
    <visual>
      <geometry>
        <mesh filename="/home/user/Desktop/ros2_ws/src/kr20_kr120_description/visual/kr20_asse3.dae" scale="0.001 0.001 0.001"/>
      </geometry>
      <origin rpy="0 0 0" xyz="-0.16 0 -1.3"/>
    </visual>
    <collision>
      <geometry>
        <mesh filename="/home/user/Desktop/ros2_ws/src/kr20_kr120_description/collision/kr20_asse3.stl" scale="0.001 0.001 0.001"/>
      </geometry>
      <origin rpy="0 0 0" xyz="-0.16 0 -1.3"/>
    </collision>
  </link>
  <joint name="kr20_link2__link3" type="revolute">
    <parent link="kr20_link2"/>
    <child link="kr20_link3"/>
    <axis xyz="0 1 0"/>
    <limit effort="100" lower="-3.97935" upper="1.48353" velocity="3.31613"/>
    <origin rpy="0 0 0" xyz="0 0 0.78"/>
    <dynamics damping="40" friction="10"/>
  </joint>
  <link name="kr20_link4">
    <inertial>
      <origin rpy="0 0 0" xyz="-0.393 0 -1.45"/>
      <mass value="1"/>
      <inertia ixx="0.00565" ixy="0" ixz="0" iyy="0" iyz="0" izz="0.00565"/>
    </inertial>
    <visual>
      <geometry>
        <mesh filename="/home/user/Desktop/ros2_ws/src/kr20_kr120_description/visual/kr20_asse4.dae" scale="0.001 0.001 0.001"/>
      </geometry>
      <origin rpy="0 0 0" xyz="-0.393 0 -1.45"/>
    </visual>
    <collision>
      <geometry>
        <mesh filename="/home/user/Desktop/ros2_ws/src/kr20_kr120_description/collision/kr20_asse4.stl" scale="0.001 0.001 0.001"/>
      </geometry>
      <origin rpy="0 0 0" xyz="-0.393 0 -1.45"/>
    </collision>
  </link>
  <joint name="kr20_link3__link4" type="revolute">
    <parent link="kr20_link3"/>
    <child link="kr20_link4"/>
    <axis xyz="1 0 0"/>
    <limit effort="100" lower="-6.10865" upper="6.10865" velocity="7.50492"/>
    <origin rpy="0 0 0" xyz="0.233 0 0.15"/>
    <dynamics damping="40" friction="10"/>
  </joint>
  <link name="kr20_link5">
    <inertial>
      <origin rpy="0 0 0" xyz="-1.02 0 -1.45"/>
      <mass value="2"/>
      <inertia ixx="0.4816" ixy="0" ixz="0" iyy="0" iyz="0" izz="0.4816"/>
    </inertial>
    <visual>
      <geometry>
        <mesh filename="/home/user/Desktop/ros2_ws/src/kr20_kr120_description/visual/kr20_asse5.dae" scale="0.001 0.001 0.001"/>
      </geometry>
      <origin rpy="0 0 0" xyz="-1.02 0 -1.45"/>
    </visual>
    <collision>
      <geometry>
        <mesh filename="/home/user/Desktop/ros2_ws/src/kr20_kr120_description/collision/kr20_asse5.stl" scale="0.001 0.001 0.001"/>
      </geometry>
      <origin rpy="0 0 0" xyz="-1.02 0 -1.45"/>
    </collision>
  </link>
  <joint name="kr20_link4__link5" type="revolute">
    <parent link="kr20_link4"/>
    <child link="kr20_link5"/>
    <axis xyz="0 1 0"/>
    <limit effort="100" lower="-2.26893" upper="2.26893" velocity="7.50492"/>
    <origin rpy="0 0 0" xyz="0.627 0 0"/>
    <dynamics damping="40" friction="10"/>
  </joint>
  <!-- tool 0 ($FLANGE coordinate system in KRC controller)-->
  <!-- <link name="tool0"/> -->
  <link name="kr20_flange">
    <inertial>
      <origin rpy="0 0 0" xyz="-1.246 0 -1.45"/>
      <mass value="1"/>
      <inertia ixx="0.4816" ixy="0" ixz="0" iyy="0" iyz="0" izz="0.4816"/>
    </inertial>
    <visual>
      <geometry>
        <mesh filename="/home/user/Desktop/ros2_ws/src/kr20_kr120_description/visual/kr20_flange.dae" scale="0.001 0.001 0.001"/>
      </geometry>
      <origin rpy="0 0 0" xyz="-1.246 0 -1.45"/>
    </visual>
    <collision>
      <geometry>
        <mesh filename="/home/user/Desktop/ros2_ws/src/kr20_kr120_description/collision/kr20_flange.stl" scale="0.001 0.001 0.001"/>
      </geometry>
      <origin rpy="0 0 0" xyz="-1.246 0 -1.45"/>
    </collision>
  </link>
  <joint name="kr20_link5__flange" type="revolute">
    <parent link="kr20_link5"/>
    <child link="kr20_flange"/>
    <axis xyz="1 0 0"/>
    <limit effort="100" lower="-6.10865" upper="6.10865" velocity="10.9956"/>
    <origin rpy="0 0 0" xyz="0.153 0 0"/>
    <dynamics damping="40" friction="10"/>
  </joint>
  <link name="kr20_wrist">
    <inertial>
      <origin rpy="0 1.5708 1.5708" xyz="0.066 0 0"/>
      <mass value="1"/>
      <inertia ixx="0.4816" ixy="0" ixz="0" iyy="0" iyz="0" izz="0.4816"/>
    </inertial>
    <visual>
      <geometry>
        <mesh filename="/home/user/Desktop/ros2_ws/src/kr20_kr120_description/visual/kr20_polso.dae" scale="0.001 0.001 0.001"/>
      </geometry>
      <origin rpy="0 1.5708 1.5708" xyz="0.066 0 0"/>
    </visual>
    <collision>
      <geometry>
        <mesh filename="/home/user/Desktop/ros2_ws/src/kr20_kr120_description/collision/kr20_polso.stl" scale="0.001 0.001 0.001"/>
      </geometry>
      <origin rpy="0 1.5708 1.5708" xyz="0.066 0 0"/>
    </collision>
  </link>
  <joint name="kr20_flange__wrist" type="fixed">
    <parent link="kr20_flange"/>
    <child link="kr20_wrist"/>
    <axis xyz="1 0 0"/>
    <limit effort="100" lower="-6.10865" upper="6.10865" velocity="10.9956"/>
    <origin rpy="0 0 0" xyz="0 0 0"/>
    <dynamics damping="40" friction="10"/>
  </joint>
  <link name="kr20_fixed">
    <inertial>
      <origin rpy="1.5708 3.1415 3.1415" xyz="0.1175 0 0"/>
      <mass value="1"/>
      <inertia ixx="0.1" ixy="0" ixz="0" iyy="0.1" iyz="0" izz="0.1"/>
    </inertial>
    <visual>
      <geometry>
        <mesh filename="/home/user/Desktop/ros2_ws/src/kr20_kr120_description/visual/kr20_fixed.dae" scale="0.001 0.001 0.001"/>
      </geometry>
      <origin rpy="1.5708 3.1415 3.1415" xyz="0.1175 0 0"/>
    </visual>
    <collision>
      <geometry>
        <mesh filename="/home/user/Desktop/ros2_ws/src/kr20_kr120_description/collision/kr20_fixed.stl" scale="0.001 0.001 0.001"/>
      </geometry>
      <origin rpy="1.5708 3.1415 3.1415" xyz="0.1175 0 0"/>
    </collision>
  </link>
  <link name="kr20_slide">
    <inertial>
      <origin rpy="-1.5708 -1.5708 0" xyz="-0.09159 0 0.252354"/>
      <mass value="1"/>
      <inertia ixx="0.1" ixy="0" ixz="0" iyy="0.1" iyz="0" izz="0.1"/>
    </inertial>
    <visual>
      <geometry>
        <mesh filename="/home/user/Desktop/ros2_ws/src/kr20_kr120_description/visual/kr20_slide.dae" scale="0.001 0.001 0.001"/>
      </geometry>
      <origin rpy="-1.5708 -1.5708 0" xyz="-0.09159 0 0.252354"/>
    </visual>
    <collision>
      <geometry>
        <mesh filename="/home/user/Desktop/ros2_ws/src/kr20_kr120_description/collision/kr20_slide.stl" scale="0.001 0.001 0.001"/>
      </geometry>
      <origin rpy="-1.5708 -1.5708 0" xyz="-0.09159 0 0.252354"/>
    </collision>
  </link>
  <joint name="kr20_tool_connector_joint" type="fixed">
    <parent link="kr20_wrist"/>
    <child link="kr20_fixed"/>
    <axis xyz="1 0 0"/>
    <limit effort="100" lower="-0.1" upper="0.5" velocity="1"/>
    <origin rpy="0 0 0" xyz="0 0 0"/>
    <dynamics damping="10" friction="10"/>
  </joint>
  <joint name="kr20_fixed_slide_joint" type="prismatic">
    <parent link="kr20_fixed"/>
    <child link="kr20_slide"/>
    <axis xyz="0 0 1"/>
    <limit effort="100" lower="-0.05121" upper="0.013863" velocity="1"/>
    <origin rpy="0 0 0" xyz="0.299605 0 -0.252354"/>
    <dynamics damping="10" friction="10"/>
  </joint>
  <transmission name="kr20_trans_fixed_slide_joint">
    <type>transmission_interface/SimpleTransmission</type>
    <joint name="kr20_fixed_slide_joint">
      <hardwareInterface>hardware_interface/EffortJointInterface</hardwareInterface>
    </joint>
    <actuator name="kr20_motor_fixed_slide_joint">
      <hardwareInterface>hardware_interface/EffortJointInterface</hardwareInterface>
      <mechanicalReduction>1</mechanicalReduction>
    </actuator>
  </transmission>
  <!-- <joint name="flange__tool0" type="fixed">
        <origin rpy="0 0 0" xyz="0 0 0"/>
        <parent link="flange"/>
        <child link="tool0"/>
    </joint>  -->
  <!-- put transmission in each joint-->
  <transmission name="kr20_trans_base_link__link1">
    <type>transmission_interface/SimpleTransmission</type>
    <joint name="kr20_base_link__link1">
      <hardwareInterface>hardware_interface/EffortJointInterface</hardwareInterface>
    </joint>
    <actuator name="kr20_motor_base_link__link1">
      <hardwareInterface>hardware_interface/EffortJointInterface</hardwareInterface>
      <mechanicalReduction>1</mechanicalReduction>
    </actuator>
  </transmission>
  <transmission name="kr20_trans_link1__link2">
    <type>transmission_interface/SimpleTransmission</type>
    <joint name="kr20_link1__link2">
      <hardwareInterface>hardware_interface/EffortJointInterface</hardwareInterface>
    </joint>
    <actuator name="kr20_motor_link1__link2">
      <hardwareInterface>hardware_interface/EffortJointInterface</hardwareInterface>
      <mechanicalReduction>1</mechanicalReduction>
    </actuator>
  </transmission>
  <transmission name="kr20_trans_link2__link3">
    <type>transmission_interface/SimpleTransmission</type>
    <joint name="kr20_link2__link3">
      <hardwareInterface>hardware_interface/EffortJointInterface</hardwareInterface>
    </joint>
    <actuator name="kr20_motor_link2__link3">
      <hardwareInterface>hardware_interface/EffortJointInterface</hardwareInterface>
      <mechanicalReduction>1</mechanicalReduction>
    </actuator>
  </transmission>
  <transmission name="kr20_trans_link3__link4">
    <type>transmission_interface/SimpleTransmission</type>
    <joint name="kr20_link3__link4">
      <hardwareInterface>hardware_interface/EffortJointInterface</hardwareInterface>
    </joint>
    <actuator name="kr20_motor_link3__link4">
      <hardwareInterface>hardware_interface/EffortJointInterface</hardwareInterface>
      <mechanicalReduction>1</mechanicalReduction>
    </actuator>
  </transmission>
  <transmission name="kr20_trans_link4__link5">
    <type>transmission_interface/SimpleTransmission</type>
    <joint name="kr20_link4__link5">
      <hardwareInterface>hardware_interface/EffortJointInterface</hardwareInterface>
    </joint>
    <actuator name="kr20_motor_link4__link5">
      <hardwareInterface>hardware_interface/EffortJointInterface</hardwareInterface>
      <mechanicalReduction>1</mechanicalReduction>
    </actuator>
  </transmission>
  <transmission name="kr20_trans_link5__flange">
    <type>transmission_interface/SimpleTransmission</type>
    <joint name="kr20_link5__flange">
      <hardwareInterface>hardware_interface/EffortJointInterface</hardwareInterface>
    </joint>
    <actuator name="kr20_motor_link5__flange">
      <hardwareInterface>hardware_interface/EffortJointInterface</hardwareInterface>
      <mechanicalReduction>1</mechanicalReduction>
    </actuator>
  </transmission>
  <link name="kr120_basamento">
    <inertial>
      <origin rpy="-1.5708 0 0" xyz="-1.265 -1.9575 0"/>
      <mass value="1"/>
      <inertia ixx="0.01625" ixy="0" ixz="0" iyy="0.01625" iyz="0" izz="0.005"/>
    </inertial>
    <visual>
      <geometry>
        <mesh filename="/home/user/Desktop/ros2_ws/src/kr20_kr120_description/visual/kr120_basement.dae" scale="0.001 0.001 0.001"/>
      </geometry>
      <origin rpy="-1.5708 0 0" xyz="-1.265 -1.9575 0"/>
    </visual>
    <collision>
      <geometry>
        <mesh filename="/home/user/Desktop/ros2_ws/src/kr20_kr120_description/collision/kr120_basement.stl" scale="0.001 0.001 0.001"/>
      </geometry>
      <origin rpy="-1.5708 0 0" xyz="-1.265 -1.9575 0"/>
    </collision>
  </link>
  <joint name="kr120_fixed" type="fixed">
    <origin rpy="0 0 1.5708" xyz="1.59 -1.430 0"/>
    <parent link="world"/>
    <child link="kr120_basamento"/>
  </joint>
  <joint name="kr120_base" type="fixed">
    <origin rpy="0 0 0" xyz="0 0 0"/>
    <parent link="kr120_basamento"/>
    <child link="kr120_base_link"/>
  </joint>
  <link name="kr120_base_link">
    <inertial>
      <origin rpy="0 0 0" xyz="0 0 0.529"/>
      <mass value="1"/>
      <inertia ixx="0.01625" ixy="0" ixz="0" iyy="0.01625" iyz="0" izz="0.005"/>
    </inertial>
    <visual>
      <geometry>
        <mesh filename="/home/user/Desktop/ros2_ws/src/kr20_kr120_description/visual/kr120_base.dae" scale="0.001 0.001 0.001"/>
      </geometry>
      <origin rpy="0 0 0" xyz="0 0 0.529"/>
    </visual>
    <collision>
      <geometry>
        <mesh filename="/home/user/Desktop/ros2_ws/src/kr20_kr120_description/collision/kr120_base.stl" scale="0.001 0.001 0.001"/>
      </geometry>
      <origin rpy="0 0 0" xyz="0 0 0.529"/>
    </collision>
  </link>
  <link name="kr120_link1">
    <inertial>
      <origin rpy="0 0 0" xyz="0 0 0.529"/>
      <mass value="1.5"/>
      <inertia ixx="0.054147" ixy="0" ixz="0" iyy="0.054147" iyz="0" izz="0.001875"/>
    </inertial>
    <visual>
      <geometry>
        <mesh filename="/home/user/Desktop/ros2_ws/src/kr20_kr120_description/visual/kr120_asse1.dae" scale="0.001 0.001 0.001"/>
      </geometry>
      <origin rpy="0 0 0" xyz="0 0 0.529"/>
    </visual>
    <collision>
      <geometry>
        <mesh filename="/home/user/Desktop/ros2_ws/src/kr20_kr120_description/collision/kr120_asse1.stl" scale="0.001 0.001 0.001"/>
      </geometry>
      <origin rpy="0 0 0" xyz="0 0 0.529"/>
    </collision>
  </link>
  <joint name="kr120_base_link__link1" type="revolute">
    <parent link="kr120_base_link"/>
    <child link="kr120_link1"/>
    <axis xyz="0 0 1"/>
    <limit effort="100" lower="-3.22886" upper="3.22886" velocity="2.0944"/>
    <origin rpy="0 0 0" xyz="0 0 0"/>
    <dynamics damping="40" friction="10"/>
  </joint>
  <link name="kr120_link2">
    <inertial>
      <origin rpy="0 0 0" xyz="-0.33 0 -0.645"/>
      <mass value="2"/>
      <inertia ixx="0.4816" ixy="0" ixz="0" iyy="0" iyz="0" izz="0.4816"/>
    </inertial>
    <visual>
      <geometry>
        <mesh filename="/home/user/Desktop/ros2_ws/src/kr20_kr120_description/visual/kr120_asse2.dae" scale="0.001 0.001 0.001"/>
      </geometry>
      <origin rpy="0 0 0" xyz="-0.33 0 -0.645"/>
    </visual>
    <collision>
      <geometry>
        <mesh filename="/home/user/Desktop/ros2_ws/src/kr20_kr120_description/collision/kr120_asse2.stl" scale="0.001 0.001 0.001"/>
      </geometry>
      <origin rpy="0 0 0" xyz="-0.33 0 -0.645"/>
    </collision>
  </link>
  <joint name="kr120_link1__link2" type="revolute">
    <parent link="kr120_link1"/>
    <child link="kr120_link2"/>
    <axis xyz="0 1 0"/>
    <limit effort="100" lower="-0.872665" upper="1.48353" velocity="2.00713"/>
    <origin rpy="0 0 0" xyz="0.33 0 1.174"/>
    <dynamics damping="40" friction="10"/>
  </joint>
  <link name="kr120_link3">
    <inertial>
      <origin rpy="0 0 0" xyz="-0.33 0.0 -1.795"/>
      <mass value="2"/>
      <inertia ixx="0.4816" ixy="0" ixz="0" iyy="0" iyz="0" izz="0.4816"/>
    </inertial>
    <visual>
      <geometry>
        <mesh filename="/home/user/Desktop/ros2_ws/src/kr20_kr120_description/visual/kr120_asse3.dae" scale="0.001 0.001 0.001"/>
      </geometry>
      <origin rpy="0 0 0" xyz="-0.33 0.0 -1.795"/>
    </visual>
    <collision>
      <geometry>
        <mesh filename="/home/user/Desktop/ros2_ws/src/kr20_kr120_description/collision/kr120_asse3.stl" scale="0.001 0.001 0.001"/>
      </geometry>
      <origin rpy="0 0 0" xyz="-0.33 0.0 -1.795"/>
    </collision>
  </link>
  <joint name="kr120_link2__link3" type="revolute">
    <parent link="kr120_link2"/>
    <child link="kr120_link3"/>
    <axis xyz="0 1 0"/>
    <limit effort="100" lower="-3.66519" upper="1.27409" velocity="2.0944"/>
    <origin rpy="0 0 0" xyz="0 0 1.15"/>
    <dynamics damping="40" friction="10"/>
  </joint>
  <link name="kr120_link4">
    <inertial>
      <origin rpy="0 0 0" xyz="-0.697 0.0 -1.910"/>
      <mass value="1"/>
      <inertia ixx="0.00565" ixy="0" ixz="0" iyy="0" iyz="0" izz="0.00565"/>
    </inertial>
    <visual>
      <geometry>
        <mesh filename="/home/user/Desktop/ros2_ws/src/kr20_kr120_description/visual/kr120_asse4.dae" scale="0.001 0.001 0.001"/>
      </geometry>
      <origin rpy="0 0 0" xyz="-0.697 0.0 -1.910"/>
    </visual>
    <collision>
      <geometry>
        <mesh filename="/home/user/Desktop/ros2_ws/src/kr20_kr120_description/collision/kr120_asse4.stl" scale="0.001 0.001 0.001"/>
      </geometry>
      <origin rpy="0 0 0" xyz="-0.697 0.0 -1.910"/>
    </collision>
  </link>
  <joint name="kr120_link3__link4" type="revolute">
    <parent link="kr120_link3"/>
    <child link="kr120_link4"/>
    <axis xyz="1 0 0"/>
    <limit effort="100" lower="-6.10865" upper="6.10865" velocity="3.31613"/>
    <origin rpy="0 0 0" xyz="0.367 0 0.115"/>
    <dynamics damping="40" friction="10"/>
  </joint>
  <link name="kr120_link5">
    <inertial>
      <origin rpy="0 0 0" xyz="-1.55 0 -1.910"/>
      <mass value="2"/>
      <inertia ixx="0.4816" ixy="0" ixz="0" iyy="0" iyz="0" izz="0.4816"/>
    </inertial>
    <visual>
      <geometry>
        <mesh filename="/home/user/Desktop/ros2_ws/src/kr20_kr120_description/visual/kr120_asse5.dae" scale="0.001 0.001 0.001"/>
      </geometry>
      <origin rpy="0 0 0" xyz="-1.55 0 -1.910"/>
    </visual>
    <collision>
      <geometry>
        <mesh filename="/home/user/Desktop/ros2_ws/src/kr20_kr120_description/collision/kr120_asse5.stl" scale="0.001 0.001 0.001"/>
      </geometry>
      <origin rpy="0 0 0" xyz="-1.55 0 -1.910"/>
    </collision>
  </link>
  <joint name="kr120_link4__link5" type="revolute">
    <parent link="kr120_link4"/>
    <child link="kr120_link5"/>
    <axis xyz="0 1 0"/>
    <limit effort="100" lower="-2.18166" upper="2.18166" velocity="3.14159"/>
    <origin rpy="0 0 0" xyz="0.853 0 0"/>
    <dynamics damping="40" friction="10"/>
  </joint>
  <!-- tool 0 ($FLANGE coordinate system in KRC controller)-->
  <!-- <link name="tool0"/> -->
  <link name="kr120_flange">
    <inertial>
      <origin rpy="0 0 0" xyz="-1.765 0 -1.910"/>
      <mass value="1"/>
      <inertia ixx="0.4816" ixy="0" ixz="0" iyy="0" iyz="0" izz="0.4816"/>
    </inertial>
    <visual>
      <geometry>
        <mesh filename="/home/user/Desktop/ros2_ws/src/kr20_kr120_description/visual/kr120_flange.dae" scale="0.001 0.001 0.001"/>
      </geometry>
      <origin rpy="0 0 0" xyz="-1.765 0 -1.910"/>
    </visual>
    <collision>
      <geometry>
        <mesh filename="/home/user/Desktop/ros2_ws/src/kr20_kr120_description/collision/kr120_flange.stl" scale="0.001 0.001 0.001"/>
      </geometry>
      <origin rpy="0 0 0" xyz="-1.765 0 -1.910"/>
    </collision>
  </link>
  <joint name="kr120_link5__flange" type="revolute">
    <parent link="kr120_link5"/>
    <child link="kr120_flange"/>
    <axis xyz="1 0 0"/>
    <limit effort="100" lower="-6.10865" upper="6.10865" velocity="4.53786"/>
    <origin rpy="0 0 0" xyz="0.215 0 0"/>
    <dynamics damping="40" friction="10"/>
  </joint>
  <link name="kr120_pinza_connector">
    <inertial>
      <origin rpy="0 0 1.5708" xyz="0 0 0"/>
      <mass value="1"/>
      <inertia ixx="0.1" ixy="0" ixz="0" iyy="0.1" iyz="0" izz="0.1"/>
    </inertial>
    <visual>
      <geometry>
        <mesh filename="/home/user/Desktop/ros2_ws/src/kr20_kr120_description/visual/kr120_slider.dae" scale="0.001 0.001 0.001"/>
      </geometry>
      <origin rpy="0 0 1.5708" xyz="0 0 0"/>
    </visual>
    <collision>
      <geometry>
        <mesh filename="/home/user/Desktop/ros2_ws/src/kr20_kr120_description/collision/kr120_slider.stl" scale="0.001 0.001 0.001"/>
      </geometry>
      <origin rpy="0 0 1.5708" xyz="0 0 0"/>
    </collision>
  </link>
  <link name="kr120_pinza_left">
    <inertial>
      <origin rpy="0 0 1.5708" xyz="0 0 0"/>
      <mass value="1"/>
      <inertia ixx="0.1" ixy="0" ixz="0" iyy="0.1" iyz="0" izz="0.1"/>
    </inertial>
    <visual>
      <geometry>
        <mesh filename="/home/user/Desktop/ros2_ws/src/kr20_kr120_description/visual/kr120_pinza_left.dae" scale="0.001 0.001 0.001"/>
      </geometry>
      <origin rpy="0 0 1.5708" xyz="0 0 0"/>
    </visual>
    <collision>
      <geometry>
        <mesh filename="/home/user/Desktop/ros2_ws/src/kr20_kr120_description/collision/kr120_pinza_left.stl" scale="0.001 0.001 0.001"/>
      </geometry>
      <origin rpy="0 0 1.5708" xyz="0 0 0"/>
    </collision>
  </link>
  <link name="kr120_pinza_right">
    <inertial>
      <origin rpy="0 0 1.5708" xyz="0 0 0"/>
      <mass value="1"/>
      <inertia ixx="0.1" ixy="0" ixz="0" iyy="0.1" iyz="0" izz="0.1"/>
    </inertial>
    <visual>
      <geometry>
        <mesh filename="/home/user/Desktop/ros2_ws/src/kr20_kr120_description/visual/kr120_pinza_right.dae" scale="0.001 0.001 0.001"/>
      </geometry>
      <origin rpy="0 0 1.5708" xyz="0 0 0"/>
    </visual>
    <collision>
      <geometry>
        <mesh filename="/home/user/Desktop/ros2_ws/src/kr20_kr120_description/collision/kr120_pinza_right.stl" scale="0.001 0.001 0.001"/>
      </geometry>
      <origin rpy="0 0 1.5708" xyz="0 0 0"/>
    </collision>
  </link>
  <link name="kr120_gyro_left">
    <inertial>
      <origin rpy="0 0 1.5708" xyz="-0.597 0 0"/>
      <mass value="1"/>
      <inertia ixx="0.1" ixy="0" ixz="0" iyy="0.1" iyz="0" izz="0.1"/>
    </inertial>
    <visual>
      <geometry>
        <mesh filename="/home/user/Desktop/ros2_ws/src/kr20_kr120_description/visual/kr120_gyro_left.dae" scale="0.001 0.001 0.001"/>
      </geometry>
      <origin rpy="0 0 1.5708" xyz="-0.597 0 0"/>
    </visual>
    <collision>
      <geometry>
        <mesh filename="/home/user/Desktop/ros2_ws/src/kr20_kr120_description/collision/kr120_gyro_left.stl" scale="0.001 0.001 0.001"/>
      </geometry>
      <origin rpy="0 0 1.5708" xyz="-0.597 0 0"/>
    </collision>
  </link>
  <link name="kr120_gyro_right">
    <inertial>
      <origin rpy="0 0 1.5708" xyz="-0.597 0 0"/>
      <mass value="1"/>
      <inertia ixx="0.1" ixy="0" ixz="0" iyy="0.1" iyz="0" izz="0.1"/>
    </inertial>
    <visual>
      <geometry>
        <mesh filename="/home/user/Desktop/ros2_ws/src/kr20_kr120_description/visual/kr120_gyro_right.dae" scale="0.001 0.001 0.001"/>
      </geometry>
      <origin rpy="0 0 1.5708" xyz="-0.597 0 0"/>
    </visual>
    <collision>
      <geometry>
        <mesh filename="/home/user/Desktop/ros2_ws/src/kr20_kr120_description/collision/kr120_gyro_right.stl" scale="0.001 0.001 0.001"/>
      </geometry>
      <origin rpy="0 0 1.5708" xyz="-0.597 0 0"/>
    </collision>
  </link>
  <joint name="kr120_pinza_connector_joint" type="fixed">
    <parent link="kr120_flange"/>
    <child link="kr120_pinza_connector"/>
    <axis xyz="0 0 1"/>
    <limit effort="0" lower="0" upper="0" velocity="0"/>
    <origin rpy="0 0 0" xyz="0 0 0"/>
    <dynamics damping="0" friction="0"/>
  </joint>
  <joint name="kr120_pinza_left_joint" type="prismatic">
    <parent link="kr120_pinza_connector"/>
    <child link="kr120_pinza_left"/>
    <axis xyz="0 1 0"/>
    <limit effort="500" lower="0" upper="0.0355" velocity="0.5"/>
    <origin rpy="0 0 0" xyz="0 0 0"/>
    <dynamics damping="0" friction="0"/>
  </joint>
  <joint name="kr120_pinza_right_joint" type="prismatic">
    <parent link="kr120_pinza_connector"/>
    <child link="kr120_pinza_right"/>
    <axis xyz="0 1 0"/>
    <limit effort="500" lower="-0.0355" upper="0" velocity="0.5"/>
    <origin rpy="0 0 0" xyz="0 0 0"/>
    <dynamics damping="0" friction="0"/>
    <!-- <mimic joint="pinza_left_joint" multiplier="-1.0" offset="0" /> -->
  </joint>
  <joint name="kr120_gyro_left_joint" type="revolute">
    <parent link="kr120_pinza_left"/>
    <child link="kr120_gyro_left"/>
    <axis xyz="0 1 0"/>
    <limit effort="1000" lower="-3.1415" upper="3.1415" velocity="4.53786"/>
    <origin rpy="0 0 0" xyz="0.597 0 0"/>
    <dynamics damping="0" friction="0"/>
  </joint>
  <joint name="kr120_gyro_right_joint" type="revolute">
    <parent link="kr120_pinza_right"/>
    <child link="kr120_gyro_right"/>
    <axis xyz="0 -1 0"/>
    <limit effort="1000" lower="-3.1415" upper="3.1415" velocity="4.53786"/>
    <origin rpy="0 0 0" xyz="0.597 0 0"/>
    <dynamics damping="0" friction="0"/>
    <!-- <mimic joint="gyro_left_joint" multiplier="-1.0" offset="0"/> -->
  </joint>
  <transmission name="kr120_trans_pinza_left_joint">
    <type>transmission_interface/SimpleTransmission</type>
    <joint name="kr120_pinza_left_joint">
      <hardwareInterface>hardware_interface/EffortJointInterface</hardwareInterface>
    </joint>
    <actuator name="kr120_motor_pinza_left_joint">
      <hardwareInterface>hardware_interface/EffortJointInterface</hardwareInterface>
      <mechanicalReduction>1</mechanicalReduction>
    </actuator>
  </transmission>
  <transmission name="kr120_trans_pinza_right_joint">
    <type>transmission_interface/SimpleTransmission</type>
    <joint name="kr120_pinza_right_joint">
      <hardwareInterface>hardware_interface/EffortJointInterface</hardwareInterface>
    </joint>
    <actuator name="kr120_motor_pinza_right_joint">
      <hardwareInterface>hardware_interface/EffortJointInterface</hardwareInterface>
      <mechanicalReduction>1</mechanicalReduction>
    </actuator>
  </transmission>
  <transmission name="kr120_trans_gyro_left_joint">
    <type>transmission_interface/SimpleTransmission</type>
    <joint name="kr120_gyro_left_joint">
      <hardwareInterface>hardware_interface/EffortJointInterface</hardwareInterface>
    </joint>
    <actuator name="kr120_motor_gyro_left_joint">
      <hardwareInterface>hardware_interface/EffortJointInterface</hardwareInterface>
      <mechanicalReduction>1</mechanicalReduction>
    </actuator>
  </transmission>
  <transmission name="kr120_trans_gyro_right_joint">
    <type>transmission_interface/SimpleTransmission</type>
    <joint name="kr120_gyro_right_joint">
      <hardwareInterface>hardware_interface/EffortJointInterface</hardwareInterface>
    </joint>
    <actuator name="kr120_motor_gyro_right_joint">
      <hardwareInterface>hardware_interface/EffortJointInterface</hardwareInterface>
      <mechanicalReduction>1</mechanicalReduction>
    </actuator>
  </transmission>
  <!-- <xacro:macro name="mimic_joint_plugin_gazebo" params="parent_joint mimic_joint has_pid:=false multiplier:=-1.0 offset:=0 sensitiveness:=0.0 max_effort:=200 robot_namespace:='/kr120r2700'">
                <gazebo>
                    <plugin name="${mimic_joint}_mimic_joint_plugin" filename="libroboticsgroup_upatras_gazebo_mimic_joint_plugin.so">
                        <joint>${parent_joint}</joint>
                        <mimicJoint>${mimic_joint}</mimicJoint>
                        <xacro:if value="${has_pid}">
                            <hasPID />
                        </xacro:if>
                        <multiplier>${multiplier}</multiplier>
                        <offset>${offset}</offset>
                        <sensitiveness>${sensitiveness}</sensitiveness>
                        <maxEffort>${max_effort}</maxEffort>
                        <xacro:unless value="${robot_namespace == '/kr120r2700'}">
                            <robotNamespace>($robot_namespace)</robotNamespace>
                        </xacro:unless>
                    </plugin>
                </gazebo>
        </xacro:macro>

        <xacro:mimic_joint_plugin_gazebo  parent_joint="pinza_right_joint" mimic_joint="pinza_left_joint" 
                                                has_pid="true" multiplier="-1.0" max_effort="200" />

        <xacro:mimic_joint_plugin_gazebo parent_joint="gyro_right_joint" mimic_joint="gyro_left_joint"
                                                has_pid="true" multiplier="-1.0" max_effort="200" />  -->
  <gazebo>
    <plugin filename="libgazebo_grasp_fix.so" name="gazebo_grasp_fix">
      <arm>
        <arm_name>kr120_pinza</arm_name>
        <palm_link>kr120_pinza_right</palm_link>
        <palm_link>kr120_pinza_left</palm_link>
        <gripper_link>kr120_gyro_left</gripper_link>
        <gripper_link>kr120_gyro_right</gripper_link>
      </arm>
      <!-- <forces_angle_tolerance>100</forces_angle_tolerance> -->
      <update_rate>50</update_rate>
      <grip_count_threshold>4</grip_count_threshold>
      <max_grip_count>25</max_grip_count>
      <release_tolerance>0.0045</release_tolerance>
      <disable_collision_on_attach>true</disable_collision_on_attach>
      <contact_topic>__default_topic__</contact_topic>
    </plugin>
  </gazebo>
  <!-- <joint name="flange__tool0" type="fixed">
        <origin rpy="0 0 0" xyz="0 0 0"/>
        <parent link="flange"/>
        <child link="tool0"/>
    </joint>                         -->
  <!-- put transmission in each joint-->
  <transmission name="kr120_trans_base_link__link1">
    <type>transmission_interface/SimpleTransmission</type>
    <joint name="kr120_base_link__link1">
      <hardwareInterface>hardware_interface/EffortJointInterface</hardwareInterface>
    </joint>
    <actuator name="kr120_motor_base_link__link1">
      <hardwareInterface>hardware_interface/EffortJointInterface</hardwareInterface>
      <mechanicalReduction>1</mechanicalReduction>
    </actuator>
  </transmission>
  <transmission name="kr120_trans_link1__link2">
    <type>transmission_interface/SimpleTransmission</type>
    <joint name="kr120_link1__link2">
      <hardwareInterface>hardware_interface/EffortJointInterface</hardwareInterface>
    </joint>
    <actuator name="kr120_motor_link1__link2">
      <hardwareInterface>hardware_interface/EffortJointInterface</hardwareInterface>
      <mechanicalReduction>1</mechanicalReduction>
    </actuator>
  </transmission>
  <transmission name="kr120_trans_link2__link3">
    <type>transmission_interface/SimpleTransmission</type>
    <joint name="kr120_link2__link3">
      <hardwareInterface>hardware_interface/EffortJointInterface</hardwareInterface>
    </joint>
    <actuator name="kr120_motor_link2__link3">
      <hardwareInterface>hardware_interface/EffortJointInterface</hardwareInterface>
      <mechanicalReduction>1</mechanicalReduction>
    </actuator>
  </transmission>
  <transmission name="kr120_trans_link3__link4">
    <type>transmission_interface/SimpleTransmission</type>
    <joint name="kr120_link3__link4">
      <hardwareInterface>hardware_interface/EffortJointInterface</hardwareInterface>
    </joint>
    <actuator name="kr120_motor_link3__link4">
      <hardwareInterface>hardware_interface/EffortJointInterface</hardwareInterface>
      <mechanicalReduction>1</mechanicalReduction>
    </actuator>
  </transmission>
  <transmission name="kr120_trans_link4__link5">
    <type>transmission_interface/SimpleTransmission</type>
    <joint name="kr120_link4__link5">
      <hardwareInterface>hardware_interface/EffortJointInterface</hardwareInterface>
    </joint>
    <actuator name="kr120_motor_link4__link5">
      <hardwareInterface>hardware_interface/EffortJointInterface</hardwareInterface>
      <mechanicalReduction>1</mechanicalReduction>
    </actuator>
  </transmission>
  <transmission name="kr120_trans_link5__flange">
    <type>transmission_interface/SimpleTransmission</type>
    <joint name="kr120_link5__flange">
      <hardwareInterface>hardware_interface/EffortJointInterface</hardwareInterface>
    </joint>
    <actuator name="kr120_motor_link5__flange">
      <hardwareInterface>hardware_interface/EffortJointInterface</hardwareInterface>
      <mechanicalReduction>1</mechanicalReduction>
    </actuator>
  </transmission>
  <ros2_control name="kr_hw" type="system">
    <!-- If you only use RViz/MoveIt (no Gazebo), use a pure fake system -->
    <hardware>
      <plugin>mock_components/GenericSystem</plugin>
    </hardware>
    <!-- KR20 joints -->
    <joint name="kr20_base_link__link1">
      <command_interface name="position"/>
      <state_interface name="position"/>
      <state_interface name="velocity"/>
    </joint>
    <joint name="kr20_link1__link2">
      <command_interface name="position"/>
      <state_interface name="position"/>
      <state_interface name="velocity"/>
    </joint>
    <joint name="kr20_link2__link3">
      <command_interface name="position"/>
      <state_interface name="position"/>
      <state_interface name="velocity"/>
    </joint>
    <joint name="kr20_link3__link4">
      <command_interface name="position"/>
      <state_interface name="position"/>
      <state_interface name="velocity"/>
    </joint>
    <joint name="kr20_link4__link5">
      <command_interface name="position"/>
      <state_interface name="position"/>
      <state_interface name="velocity"/>
    </joint>
    <joint name="kr20_link5__flange">
      <command_interface name="position"/>
      <state_interface name="position"/>
      <state_interface name="velocity"/>
    </joint>
    <!-- KR120 joints -->
    <joint name="kr120_base_link__link1">
      <command_interface name="position"/>
      <state_interface name="position"/>
      <state_interface name="velocity"/>
    </joint>
    <joint name="kr120_link1__link2">
      <command_interface name="position"/>
      <state_interface name="position"/>
      <state_interface name="velocity"/>
    </joint>
    <joint name="kr120_link2__link3">
      <command_interface name="position"/>
      <state_interface name="position"/>
      <state_interface name="velocity"/>
    </joint>
    <joint name="kr120_link3__link4">
      <command_interface name="position"/>
      <state_interface name="position"/>
      <state_interface name="velocity"/>
    </joint>
    <joint name="kr120_link4__link5">
      <command_interface name="position"/>
      <state_interface name="position"/>
      <state_interface name="velocity"/>
    </joint>
    <joint name="kr120_link5__flange">
      <command_interface name="position"/>
      <state_interface name="position"/>
      <state_interface name="velocity"/>
    </joint>
  </ros2_control>
  <!--  pareti -->
  <joint name="fixed_pareti" type="fixed">
    <parent link="world"/>
    <child link="pareti"/>
    <origin rpy="-1.5708 0 -1.5708" xyz="-0.0485 -0.5405 0"/>
  </joint>
  <link name="pareti">
    <inertial>
      <origin rpy="0 0 0" xyz="0 0 0"/>
      <mass value="2"/>
      <inertia ixx="0.01" ixy="0" ixz="0" iyy="0.01" iyz="0" izz="0.01"/>
    </inertial>
    <visual>
      <origin rpy="0 0 0" xyz="0 0 0"/>
      <geometry>
        <mesh filename="/home/user/Desktop/ros2_ws/src/kr20_kr120_description/visual/pareti.dae" scale="0.001 0.001 0.001"/>
      </geometry>
    </visual>
    <collision>
      <origin rpy="0 0 0" xyz="0 0 0"/>
      <geometry>
        <mesh filename="/home/user/Desktop/ros2_ws/src/kr20_kr120_description/collision/pareti.stl" scale="0.001 0.001 0.001"/>
      </geometry>
    </collision>
  </link>
  <link name="table">
    <inertial>
      <origin rpy="0 0 -1.5708" xyz="1.252 -0.12 0.004"/>
      <mass value="100"/>
      <inertia ixx="0.01" ixy="0" ixz="0" iyy="0.01" iyz="0" izz="0.01"/>
    </inertial>
    <visual>
      <origin rpy="0 0 -1.5708" xyz="1.252 -0.12 0.004"/>
      <geometry>
        <mesh filename="/home/user/Desktop/ros2_ws/src/kr20_kr120_description/visual/tavolo.dae" scale="0.001 0.001 0.001"/>
      </geometry>
    </visual>
    <collision>
      <origin rpy="0 0 0" xyz="1.252 -0.12 0.413"/>
      <geometry>
        <box size="1.25 1.2 0.818"/>
      </geometry>
    </collision>
    <collision>
      <origin rpy="0 0 0" xyz="1.351333 0.293226 1.101617"/>
      <geometry>
        <box size="0.04 0.15 0.01"/>
      </geometry>
    </collision>
    <collision>
      <origin rpy="0 0 0" xyz="1.351333 -0.025761 1.101617"/>
      <geometry>
        <box size="0.04 0.15 0.01"/>
      </geometry>
    </collision>
    <collision>
      <origin rpy="0 0 0" xyz="0.672197 -0.025761 1.101617"/>
      <geometry>
        <box size="0.04 0.15 0.01"/>
      </geometry>
    </collision>
    <collision>
      <origin rpy="0 0 0" xyz="0.672197 0.293226 1.101617"/>
      <geometry>
        <box size="0.04 0.15 0.01"/>
      </geometry>
    </collision>
  </link>
  <joint name="fixed_table" type="fixed">
    <parent link="world"/>
    <child link="table"/>
    <origin rpy="0 0 0" xyz="0 0 0"/>
  </joint>
  <!-- fine pareti -->
  <!-- rulliera -->
  <joint name="rl_fixed" type="fixed">
    <origin rpy="0 0 0" xyz="0 -1.430 0.01"/>
    <parent link="world"/>
    <child link="rl_base"/>
  </joint>
  <!--links-->
  <link name="rl_base">
    <inertial>
      <origin rpy="0 0 1.5708" xyz="0.096703 0 0.65625"/>
      <mass value="1000"/>
      <inertia ixx="0.1" ixy="0.1" ixz="0.1" iyy="0.1" iyz="0.1" izz="0.1"/>
    </inertial>
    <visual>
      <geometry>
        <mesh filename="/home/user/Desktop/ros2_ws/src/kr20_kr120_description/visual/rl_infrastruttura.dae" scale="0.001 0.001 0.001"/>
      </geometry>
      <origin rpy="0 0 1.5708" xyz="0.096703 0 0.65625"/>
    </visual>
    <collision>
      <geometry>
        <mesh filename="/home/user/Desktop/ros2_ws/src/kr20_kr120_description/collision/rl_infrastruttura.stl" scale="0.001 0.001 0.001"/>
      </geometry>
      <origin rpy="0 0 1.5708" xyz="0.096703 0 0.65625"/>
    </collision>
  </link>
  <link name="rl_plate">
    <inertial>
      <origin rpy="0 0 0" xyz="0 0 0.473"/>
      <mass value="100"/>
      <inertia ixx="0.1" ixy="0.1" ixz="0.1" iyy="0.1" iyz="0.1" izz="0.1"/>
    </inertial>
    <visual>
      <geometry>
        <mesh filename="/home/user/Desktop/ros2_ws/src/kr20_kr120_description/visual/rl_piastra.dae" scale="0.001 0.001 0.001"/>
      </geometry>
      <origin rpy="0 0 0" xyz="0 0 0.473"/>
    </visual>
    <collision>
      <geometry>
        <mesh filename="/home/user/Desktop/ros2_ws/src/kr20_kr120_description/collision/rl_piastra.stl" scale="0.001 0.001 0.001"/>
      </geometry>
      <origin rpy="0 0 0" xyz="0 0 0.473"/>
    </collision>
  </link>
  <link name="rl_slider">
    <inertial>
      <origin rpy="0 0 0" xyz="0 0 0.473"/>
      <mass value="100"/>
      <inertia ixx="0.1" ixy="0.1" ixz="0.1" iyy="0.1" iyz="0.1" izz="0.1"/>
    </inertial>
    <visual>
      <geometry>
        <box size="0.0001 0.0001 0.0001"/>
      </geometry>
      <origin rpy="0 0 0" xyz="0 0 0.473"/>
    </visual>
    <collision>
      <geometry>
        <box size="0.0001 0.0001 0.0001"/>
      </geometry>
      <origin rpy="0 0 0" xyz="0 0 0.473"/>
    </collision>
  </link>
  <link name="rl_lifter">
    <inertial>
      <origin rpy="1.5708 0 1.5708" xyz="-0.3455 0 -0.02"/>
      <mass value="100"/>
      <inertia ixx="0.1" ixy="0.1" ixz="0.1" iyy="0.1" iyz="0.1" izz="0.1"/>
    </inertial>
    <visual>
      <geometry>
        <mesh filename="/home/user/Desktop/ros2_ws/src/kr20_kr120_description/visual/rl_lifter.dae" scale="0.001 0.001 0.001"/>
      </geometry>
      <origin rpy="1.5708 0 1.5708" xyz="-0.3455 0 -0.02"/>
    </visual>
    <collision>
      <geometry>
        <mesh filename="/home/user/Desktop/ros2_ws/src/kr20_kr120_description/collision/rl_lifter.stl" scale="0.001 0.001 0.001"/>
      </geometry>
      <origin rpy="1.5708 0 1.5708" xyz="-0.3455 0 -0.02"/>
    </collision>
  </link>
  <!--joints-->
  <joint name="rl_slider__plate" type="revolute">
    <parent link="rl_slider"/>
    <child link="rl_plate"/>
    <axis xyz="0 0 1"/>
    <limit effort="100" lower="0" upper="6.283185307" velocity="2"/>
    <origin rpy="0 0 0" xyz="0 0 0"/>
  </joint>
  <joint name="rl_base__lifter" type="prismatic">
    <parent link="rl_base"/>
    <child link="rl_lifter"/>
    <axis xyz="0 0 1"/>
    <limit effort="100" lower="0" upper="0.24" velocity="2"/>
    <origin rpy="0 0 0" xyz="0 0 0"/>
  </joint>
  <joint name="rl_base__slider" type="prismatic">
    <parent link="rl_base"/>
    <child link="rl_slider"/>
    <axis xyz="1 0 0"/>
    <limit effort="100" lower="-1.031" upper="0" velocity="2"/>
    <origin rpy="0 0 0" xyz="0 0 0"/>
  </joint>
  <!--transmission-->
  <transmission name="rl_trans_base__lifter">
    <type>transmission_interface/SimpleTransmission</type>
    <joint name="rl_base__lifter">
      <hardwareInterface>hardware_interface/EffortJointInterface</hardwareInterface>
    </joint>
    <actuator name="rl_motor_base__lifter">
      <hardwareInterface>hardware_interface/EffortJointInterface</hardwareInterface>
      <mechanicalReduction>1</mechanicalReduction>
    </actuator>
  </transmission>
  <transmission name="rl_trans_base__slider">
    <type>transmission_interface/SimpleTransmission</type>
    <joint name="rl_base__slider">
      <hardwareInterface>hardware_interface/EffortJointInterface</hardwareInterface>
    </joint>
    <actuator name="rl_motor_base__slider">
      <hardwareInterface>hardware_interface/EffortJointInterface</hardwareInterface>
      <mechanicalReduction>1</mechanicalReduction>
    </actuator>
  </transmission>
  <transmission name="rl_trans_slider__plate">
    <type>transmission_interface/SimpleTransmission</type>
    <joint name="rl_slider__plate">
      <hardwareInterface>hardware_interface/EffortJointInterface</hardwareInterface>
    </joint>
    <actuator name="rl_motor_slider__plate">
      <hardwareInterface>hardware_interface/EffortJointInterface</hardwareInterface>
      <mechanicalReduction>1</mechanicalReduction>
    </actuator>
  </transmission>
  <!-- fine rulliera -->
  <!-- Gazebo plugin-->
  <gazebo>
    <plugin filename="libgazebo_ros2_control.so" name="gazebo_ros2_control">
      <!-- Optional: point to your ros2_control YAML -->
      <!-- <parameters>$(find-pkg-share kr20_kr120_moveit_config)/config/ros2_controllers.yaml</parameters> -->
    </plugin>
  </gazebo>
  <gazebo reference="kr20_base_link">
    <gravity>0</gravity>
  </gazebo>
  <gazebo reference="kr20_link1">
    <gravity>0</gravity>
  </gazebo>
  <gazebo reference="kr20_link2">
    <gravity>0</gravity>
  </gazebo>
  <gazebo reference="kr20_link3">
    <gravity>0</gravity>
  </gazebo>
  <gazebo reference="kr20_link4">
    <gravity>0</gravity>
  </gazebo>
  <gazebo reference="kr20_link5">
    <gravity>0</gravity>
  </gazebo>
  <gazebo reference="kr20_fixed">
    <gravity>0</gravity>
  </gazebo>
  <gazebo reference="kr20_slide">
    <gravity>0</gravity>
  </gazebo>
  <gazebo reference="kr120_base_link">
    <gravity>0</gravity>
  </gazebo>
  <gazebo reference="kr120_link1">
    <gravity>0</gravity>
  </gazebo>
  <gazebo reference="kr120_link2">
    <gravity>0</gravity>
  </gazebo>
  <gazebo reference="kr120_link3">
    <gravity>0</gravity>
  </gazebo>
  <gazebo reference="kr120_link4">
    <gravity>0</gravity>
  </gazebo>
  <gazebo reference="kr120_link5">
    <gravity>0</gravity>
  </gazebo>
  <gazebo reference="kr120_pinza_right">
    <gravity>0</gravity>
  </gazebo>
  <gazebo reference="kr120_pinza_left">
    <gravity>0</gravity>
  </gazebo>
  <gazebo reference="kr120_gyro_right">
    <gravity>0</gravity>
  </gazebo>
  <gazebo reference="kr120_gyro_left">
    <gravity>0</gravity>
  </gazebo>
  <gazebo reference="kr120_pinza_connector">
    <gravity>0</gravity>
  </gazebo>
  <gazebo reference="rl_base">
    <gravity>0</gravity>
  </gazebo>
  <gazebo reference="rl_plate">
    <gravity>0</gravity>
  </gazebo>
  <gazebo reference="rl_lifter">
    <gravity>0</gravity>
  </gazebo>
  <gazebo reference="rl_slider">
    <gravity>0</gravity>
  </gazebo>
</robot>
